Workbook

Sheet MP Cyber 2026
B2: zenda.
B3: Sancor Seguros | Media Plan Cyber Monday 2026
B4: Versión de ejemplo: presupuesto, productos y fechas pendientes de confirmar (celdas en rosa en Supuestos).
B6: RESUMEN POR ETAPA Y PRODUCTO | J6: RESUMEN POR MEDIO
B7: Producto | C7: Etapa | D7: Inversión | E7: % del total | F7: Conversiones | G7: CPA | H7: Clicks | J7: Medio | K7: Inversión | L7: % del total | M7: Conversiones | N7: CPA
B8: Teaser | C8: Teaser | D8: =F32 | E8: =IFERROR(D8/$D$13,"") | F8: - | G8: - | H8: =L32 | J8: Google Ads | K8: =SUMIF($C$28:$C$65,J8,$F$28:$F$65) | L8: =IFERROR(K8/$K$10,"") | M8: =SUMIF($C$36:$C$65,J8,$N$36:$N$65) | N8: =IFERROR(SUMIF($C$36:$C$65,J8,$F$36:$F$65)/M8,"")
B9: Auto | C9: Performance | D9: =F40 | E9: =IFERROR(D9/$D$13,"") | F9: =N40 | G9: =IFERROR(D9/F9,"") | H9: =L40 | J9: Meta Ads | K9: =SUMIF($C$28:$C$65,J9,$F$28:$F$65) | L9: =IFERROR(K9/$K$10,"") | M9: =SUMIF($C$36:$C$65,J9,$N$36:$N$65) | N9: =IFERROR(SUMIF($C$36:$C$65,J9,$F$36:$F$65)/M9,"")
B10: Moto | C10: Performance | D10: =F48 | E10: =IFERROR(D10/$D$13,"") | F10: =N48 | G10: =IFERROR(D10/F10,"") | H10: =L48 | J10: TOTAL | K10: =SUM(K8:K9) | L10: =SUM(L8:L9) | M10: =SUM(M8:M9) | N10: =IFERROR(SUM(D9:D12)/M10,)
B11: Movilidad | C11: Performance | D11: =F56 | E11: =IFERROR(D11/$D$13,"") | F11: =N56 | G11: =IFERROR(D11/F11,"") | H11: =L56
B12: Hogar | C12: Performance | D12: =F63 | E12: =IFERROR(D12/$D$13,"") | F12: =N63 | G12: =IFERROR(D12/F12,"") | H12: =L63
B13: TOTAL | D13: =SUM(D8:D12) | E13: =SUM(E8:E12) | F13: =SUM(F9:F12) | G13: =IFERROR(SUM(D9:D12)/F13,"") | H13: =SUM(H8:H12)
B14: CPA total calculado solo sobre Performance (el teaser no lleva conversiones).
B16: FECHAS | J16: CONTROLES
B17: Teaser | C17: =Supuestos!$C$8 | D17: =Supuestos!$D$8 | J17: Detalle = presupuesto | M17: =IF(ROUND(D13-Supuestos!D18,0)=0,"OK","REVISAR")
B18: Cyber Monday + Cyber Week | C18: =Supuestos!$C$9 | D18: =Supuestos!D9 | J18: Medios = total | M18: =IF(ROUND(K10-D13,0)=0,"OK","REVISAR")
B19: Presupuesto total | C19: =Supuestos!D18 | J19: % de cada bloque = 100 % | M19: =IF(AND(ROUND(E32,4)=1,ROUND(E40,4)=1,ROUND(E48,4)=1,ROUND(E56,4)=1,ROUND(E63,4)=1),"OK","REVISAR")
J20: Curva diaria = 100 % | M20: =IF(ROUND(Supuestos!C32,4)=1,"OK","REVISAR")
B26: DETALLE POR CAMPAÑA
B28: Teaser
B29: Campaña | C29: Medio | D29: Estrategia | E29: % | F29: Inversión | G29: CPM | H29: CPC | L29: Clicks | M29: Impresiones | N29: CTR | Q29: Inv. diaria prom.
B30: DEMAND GEN - TRÁFICO | C30: Google Ads | D30: TRÁFICO | E30: 0.5 | F30: =E30*Supuestos!$D$13 | G30: 325.17 | H30: 10.62 | L30: =IFERROR(F30/H30,"") | M30: =IFERROR(F30/G30*1000,"") | N30: =IFERROR(L30/M30,"") | Q30: =IFERROR(F30/Supuestos!$E$8,"")
B31: META - TRÁFICO | C31: Meta Ads | D31: TRÁFICO | E31: 0.5 | F31: =E31*Supuestos!$D$13 | G31: 400 | H31: 37.1 | L31: =IFERROR(F31/H31,"") | M31: =IFERROR(F31/G31*1000,"") | N31: =IFERROR(L31/M31,"") | Q31: =IFERROR(F31/Supuestos!$E$8,"")
B32: Subtotal Teaser | E32: =SUM(E30:E31) | F32: =SUM(F30:F31) | L32: =SUM(L30:L31) | M32: =SUM(M30:M31) | N32: =IFERROR(L32/M32,"") | Q32: =SUM(Q30:Q31)
B34: Performance Auto
B35: Campaña | C35: Medio | D35: Estrategia | E35: % | F35: Inversión | G35: CPC | H35: CTR | I35: CR base | J35: Ajuste | K35: CR Cyber | L35: Clicks | M35: Impresiones | N35: Conversiones | O35: CPA | P35: CPM | Q35: Inv. diaria prom.
B36: GOOGLE SEARCH - BRAND | C36: Google Ads | D36: CONVERSIONES | E36: 0.32 | F36: =E36*Supuestos!$D$14 | G36: 542.37 | H36: 0.3084 | I36: 0.014 | J36: =Supuestos!$F$22 | K36: =I36*J36 | L36: =IFERROR(F36/G36,"") | M36: =IFERROR(L36/H36,"") | N36: =IFERROR(L36*K36,"") | O36: =IFERROR(F36/N36,"") | P36: =IFERROR(F36/M36*1000,"") | Q36: =IFERROR(F36/Supuestos!$E$9,"")
B37: GOOGLE SEARCH - NOT BRAND | C37: Google Ads | D37: CONVERSIONES | E37: 0.26 | F37: =E37*Supuestos!$D$14 | G37: 3108.27 | H37: 0.0572 | I37: 0.0581 | J37: =Supuestos!$F$22 | K37: =I37*J37 | L37: =IFERROR(F37/G37,"") | M37: =IFERROR(L37/H37,"") | N37: =IFERROR(L37*K37,"") | O37: =IFERROR(F37/N37,"") | P37: =IFERROR(F37/M37*1000,"") | Q37: =IFERROR(F37/Supuestos!$E$9,"")
B38: PERFORMANCE MAX | C38: Google Ads | D38: CONVERSIONES | E38: 0.37 | F38: =E38*Supuestos!$D$14 | G38: 547.06 | H38: 0.0143 | I38: 0.0278 | J38: =Supuestos!$F$22 | K38: =I38*J38 | L38: =IFERROR(F38/G38,"") | M38: =IFERROR(L38/H38,"") | N38: =IFERROR(L38*K38,"") | O38: =IFERROR(F38/N38,"") | P38: =IFERROR(F38/M38*1000,"") | Q38: =IFERROR(F38/Supuestos!$E$9,"")
B39: META | C39: Meta Ads | D39: CONVERSIONES | E39: 0.05 | F39: =E39*Supuestos!$D$14 | G39: 246.54 | H39: 0.0055 | I39: 0.0067 | J39: =Supuestos!$F$22 | K39: =I39*J39 | L39: =IFERROR(F39/G39,"") | M39: =IFERROR(L39/H39,"") | N39: =IFERROR(L39*K39,"") | O39: =IFERROR(F39/N39,"") | P39: =IFERROR(F39/M39*1000,"") | Q39: =IFERROR(F39/Supuestos!$E$9,"")
B40: Subtotal Auto | E40: =SUM(E36:E39) | F40: =SUM(F36:F39) | G40: =IFERROR(F40/L40,"") | H40: =IFERROR(L40/M40,"") | K40: =IFERROR(N40/L40,"") | L40: =SUM(L36:L39) | M40: =SUM(M36:M39) | N40: =SUM(N36:N39) | O40: =IFERROR(F40/N40,"") | P40: =IFERROR(F40/M40*1000,"") | Q40: =SUM(Q36:Q39)
B42: Performance Moto
B43: Campaña | C43: Medio | D43: Estrategia | E43: % | F43: Inversión | G43: CPC | H43: CTR | I43: CR base | J43: Ajuste | K43: CR Cyber | L43: Clicks | M43: Impresiones | N43: Conversiones | O43: CPA | P43: CPM | Q43: Inv. diaria prom.
B44: SEM - BRAND | C44: Google Ads | D44: CONVERSIONES | E44: 0.16 | F44: =E44*Supuestos!$D$15 | G44: 270.3 | H44: 0.6377 | I44: 0.1538 | J44: =Supuestos!$F$23 | K44: =I44*J44 | L44: =IFERROR(F44/G44,"") | M44: =IFERROR(L44/H44,"") | N44: =IFERROR(L44*K44,"") | O44: =IFERROR(F44/N44,"") | P44: =IFERROR(F44/M44*1000,"") | Q44: =IFERROR(F44/Supuestos!$E$9,"")
B45: SEM - CATEGORÍA | C45: Google Ads | D45: CONVERSIONES | E45: 0.26 | F45: =E45*Supuestos!$D$15 | G45: 187.97 | H45: 0.1514 | I45: 0.1568 | J45: =Supuestos!$F$23 | K45: =I45*J45 | L45: =IFERROR(F45/G45,"") | M45: =IFERROR(L45/H45,"") | N45: =IFERROR(L45*K45,"") | O45: =IFERROR(F45/N45,"") | P45: =IFERROR(F45/M45*1000,"") | Q45: =IFERROR(F45/Supuestos!$E$9,"")
B46: PERFORMANCE MAX | C46: Google Ads | D46: CONVERSIONES | E46: 0.53 | F46: =E46*Supuestos!$D$15 | G46: 244.1 | H46: 0.0419 | I46: 0.204 | J46: =Supuestos!$F$23 | K46: =I46*J46 | L46: =IFERROR(F46/G46,"") | M46: =IFERROR(L46/H46,"") | N46: =IFERROR(L46*K46,"") | O46: =IFERROR(F46/N46,"") | P46: =IFERROR(F46/M46*1000,"") | Q46: =IFERROR(F46/Supuestos!$E$9,"")
B47: META | C47: Meta Ads | D47: CONVERSIONES | E47: 0.05 | F47: =E47*Supuestos!$D$15 | G47: 292.91 | H47: 0.0136 | I47: 0.1086 | J47: =Supuestos!$F$23 | K47: =I47*J47 | L47: =IFERROR(F47/G47,"") | M47: =IFERROR(L47/H47,"") | N47: =IFERROR(L47*K47,"") | O47: =IFERROR(F47/N47,"") | P47: =IFERROR(F47/M47*1000,"") | Q47: =IFERROR(F47/Supuestos!$E$9,"")
B48: Subtotal Moto | E48: =SUM(E44:E47) | F48: =SUM(F44:F47) | G48: =IFERROR(F48/L48,"") | H48: =IFERROR(L48/M48,"") | K48: =IFERROR(N48/L48,"") | L48: =SUM(L44:L47) | M48: =SUM(M44:M47) | N48: =SUM(N44:N47) | O48: =IFERROR(F48/N48,"") | P48: =IFERROR(F48/M48*1000,"") | Q48: =SUM(Q44:Q47)
B50: Performance Movilidad
B51: Campaña | C51: Medio | D51: Estrategia | E51: % | F51: Inversión | G51: CPC | H51: CTR | I51: CR base | J51: Ajuste | K51: CR Cyber | L51: Clicks | M51: Impresiones | N51: Conversiones | O51: CPA | P51: CPM | Q51: Inv. diaria prom.
B52: SEM - BRAND | C52: Google Ads | D52: CONVERSIONES | E52: 0.07 | F52: =E52*Supuestos!$D$16 | G52: 1742.57 | H52: 0.3835 | I52: 0.1191 | J52: =Supuestos!$F$24 | K52: =I52*J52 | L52: =IFERROR(F52/G52,"") | M52: =IFERROR(L52/H52,"") | N52: =IFERROR(L52*K52,"") | O52: =IFERROR(F52/N52,"") | P52: =IFERROR(F52/M52*1000,"") | Q52: =IFERROR(F52/Supuestos!$E$9,"")
...

Sheet BGT Diario
B2: zenda.
B3: Sancor Seguros | Cyber Monday 2026 · Inversión diaria
B4: Semana Cyber: inversión de cada campaña × curva diaria de Supuestos. Teaser: inversión pareja por día.
B6: SEMANA CYBER
B7: Performance Auto
B8: Campaña | C8: Inversión | D8: =Supuestos!C30 | E8: =Supuestos!D30 | F8: =Supuestos!E30 | G8: =Supuestos!F30 | H8: =Supuestos!G30 | I8: =Supuestos!H30 | J8: =Supuestos!I30 | K8: Control
B9: ='MP Cyber 2026'!B36 | C9: ='MP Cyber 2026'!F36 | D9: =$C9*Supuestos!C$31 | E9: =$C9*Supuestos!D$31 | F9: =$C9*Supuestos!E$31 | G9: =$C9*Supuestos!F$31 | H9: =$C9*Supuestos!G$31 | I9: =$C9*Supuestos!H$31 | J9: =$C9*Supuestos!I$31 | K9: =SUM(D9:J9)-C9
B10: ='MP Cyber 2026'!B37 | C10: ='MP Cyber 2026'!F37 | D10: =$C10*Supuestos!C$31 | E10: =$C10*Supuestos!D$31 | F10: =$C10*Supuestos!E$31 | G10: =$C10*Supuestos!F$31 | H10: =$C10*Supuestos!G$31 | I10: =$C10*Supuestos!H$31 | J10: =$C10*Supuestos!I$31 | K10: =SUM(D10:J10)-C10
B11: ='MP Cyber 2026'!B38 | C11: ='MP Cyber 2026'!F38 | D11: =$C11*Supuestos!C$31 | E11: =$C11*Supuestos!D$31 | F11: =$C11*Supuestos!E$31 | G11: =$C11*Supuestos!F$31 | H11: =$C11*Supuestos!G$31 | I11: =$C11*Supuestos!H$31 | J11: =$C11*Supuestos!I$31 | K11: =SUM(D11:J11)-C11
B12: ='MP Cyber 2026'!B39 | C12: ='MP Cyber 2026'!F39 | D12: =$C12*Supuestos!C$31 | E12: =$C12*Supuestos!D$31 | F12: =$C12*Supuestos!E$31 | G12: =$C12*Supuestos!F$31 | H12: =$C12*Supuestos!G$31 | I12: =$C12*Supuestos!H$31 | J12: =$C12*Supuestos!I$31 | K12: =SUM(D12:J12)-C12
B13: Subtotal Auto | C13: =SUM(C9:C12) | D13: =SUM(D9:D12) | E13: =SUM(E9:E12) | F13: =SUM(F9:F12) | G13: =SUM(G9:G12) | H13: =SUM(H9:H12) | I13: =SUM(I9:I12) | J13: =SUM(J9:J12) | K13: =SUM(K9:K12)
B15: Performance Moto
B16: Campaña | C16: Inversión | D16: =Supuestos!C30 | E16: =Supuestos!D30 | F16: =Supuestos!E30 | G16: =Supuestos!F30 | H16: =Supuestos!G30 | I16: =Supuestos!H30 | J16: =Supuestos!I30 | K16: Control
B17: ='MP Cyber 2026'!B44 | C17: ='MP Cyber 2026'!F44 | D17: =$C17*Supuestos!C$31 | E17: =$C17*Supuestos!D$31 | F17: =$C17*Supuestos!E$31 | G17: =$C17*Supuestos!F$31 | H17: =$C17*Supuestos!G$31 | I17: =$C17*Supuestos!H$31 | J17: =$C17*Supuestos!I$31 | K17: =SUM(D17:J17)-C17
B18: ='MP Cyber 2026'!B45 | C18: ='MP Cyber 2026'!F45 | D18: =$C18*Supuestos!C$31 | E18: =$C18*Supuestos!D$31 | F18: =$C18*Supuestos!E$31 | G18: =$C18*Supuestos!F$31 | H18: =$C18*Supuestos!G$31 | I18: =$C18*Supuestos!H$31 | J18: =$C18*Supuestos!I$31 | K18: =SUM(D18:J18)-C18
B19: ='MP Cyber 2026'!B46 | C19: ='MP Cyber 2026'!F46 | D19: =$C19*Supuestos!C$31 | E19: =$C19*Supuestos!D$31 | F19: =$C19*Supuestos!E$31 | G19: =$C19*Supuestos!F$31 | H19: =$C19*Supuestos!G$31 | I19: =$C19*Supuestos!H$31 | J19: =$C19*Supuestos!I$31 | K19: =SUM(D19:J19)-C19
B20: ='MP Cyber 2026'!B47 | C20: ='MP Cyber 2026'!F47 | D20: =$C20*Supuestos!C$31 | E20: =$C20*Supuestos!D$31 | F20: =$C20*Supuestos!E$31 | G20: =$C20*Supuestos!F$31 | H20: =$C20*Supuestos!G$31 | I20: =$C20*Supuestos!H$31 | J20: =$C20*Supuestos!I$31 | K20: =SUM(D20:J20)-C20
B21: Subtotal Moto | C21: =SUM(C17:C20) | D21: =SUM(D17:D20) | E21: =SUM(E17:E20) | F21: =SUM(F17:F20) | G21: =SUM(G17:G20) | H21: =SUM(H17:H20) | I21: =SUM(I17:I20) | J21: =SUM(J17:J20) | K21: =SUM(K17:K20)
B23: Performance Movilidad
B24: Campaña | C24: Inversión | D24: =Supuestos!C30 | E24: =Supuestos!D30 | F24: =Supuestos!E30 | G24: =Supuestos!F30 | H24: =Supuestos!G30 | I24: =Supuestos!H30 | J24: =Supuestos!I30 | K24: Control
B25: ='MP Cyber 2026'!B52 | C25: ='MP Cyber 2026'!F52 | D25: =$C25*Supuestos!C$31 | E25: =$C25*Supuestos!D$31 | F25: =$C25*Supuestos!E$31 | G25: =$C25*Supuestos!F$31 | H25: =$C25*Supuestos!G$31 | I25: =$C25*Supuestos!H$31 | J25: =$C25*Supuestos!I$31 | K25: =SUM(D25:J25)-C25
B26: ='MP Cyber 2026'!B53 | C26: ='MP Cyber 2026'!F53 | D26: =$C26*Supuestos!C$31 | E26: =$C26*Supuestos!D$31 | F26: =$C26*Supuestos!E$31 | G26: =$C26*Supuestos!F$31 | H26: =$C26*Supuestos!G$31 | I26: =$C26*Supuestos!H$31 | J26: =$C26*Supuestos!I$31 | K26: =SUM(D26:J26)-C26
B27: ='MP Cyber 2026'!B54 | C27: ='MP Cyber 2026'!F54 | D27: =$C27*Supuestos!C$31 | E27: =$C27*Supuestos!D$31 | F27: =$C27*Supuestos!E$31 | G27: =$C27*Supuestos!F$31 | H27: =$C27*Supuestos!G$31 | I27: =$C27*Supuestos!H$31 | J27: =$C27*Supuestos!I$31 | K27: =SUM(D27:J27)-C27
B28: ='MP Cyber 2026'!B55 | C28: ='MP Cyber 2026'!F55 | D28: =$C28*Supuestos!C$31 | E28: =$C28*Supuestos!D$31 | F28: =$C28*Supuestos!E$31 | G28: =$C28*Supuestos!F$31 | H28: =$C28*Supuestos!G$31 | I28: =$C28*Supuestos!H$31 | J28: =$C28*Supuestos!I$31 | K28: =SUM(D28:J28)-C28
B29: Subtotal Movilidad | C29: =SUM(C25:C28) | D29: =SUM(D25:D28) | E29: =SUM(E25:E28) | F29: =SUM(F25:F28) | G29: =SUM(G25:G28) | H29: =SUM(H25:H28) | I29: =SUM(I25:I28) | J29: =SUM(J25:J28) | K29: =SUM(K25:K28)
B31: Performance Hogar
B32: Campaña | C32: Inversión | D32: =Supuestos!C30 | E32: =Supuestos!D30 | F32: =Supuestos!E30 | G32: =Supuestos!F30 | H32: =Supuestos!G30 | I32: =Supuestos!H30 | J32: =Supuestos!I30 | K32: Control
B33: ='MP Cyber 2026'!B60 | C33: ='MP Cyber 2026'!F60 | D33: =$C33*Supuestos!C$31 | E33: =$C33*Supuestos!D$31 | F33: =$C33*Supuestos!E$31 | G33: =$C33*Supuestos!F$31 | H33: =$C33*Supuestos!G$31 | I33: =$C33*Supuestos!H$31 | J33: =$C33*Supuestos!I$31 | K33: =SUM(D33:J33)-C33
B34: ='MP Cyber 2026'!B61 | C34: ='MP Cyber 2026'!F61 | D34: =$C34*Supuestos!C$31 | E34: =$C34*Supuestos!D$31 | F34: =$C34*Supuestos!E$31 | G34: =$C34*Supuestos!F$31 | H34: =$C34*Supuestos!G$31 | I34: =$C34*Supuestos!H$31 | J34: =$C34*Supuestos!I$31 | K34: =SUM(D34:J34)-C34
B35: ='MP Cyber 2026'!B62 | C35: ='MP Cyber 2026'!F62 | D35: =$C35*Supuestos!C$31 | E35: =$C35*Supuestos!D$31 | F35: =$C35*Supuestos!E$31 | G35: =$C35*Supuestos!F$31 | H35: =$C35*Supuestos!G$31 | I35: =$C35*Supuestos!H$31 | J35: =$C35*Supuestos!I$31 | K35: =SUM(D35:J35)-C35
B36: Subtotal Hogar | C36: =SUM(C33:C35) | D36: =SUM(D33:D35) | E36: =SUM(E33:E35) | F36: =SUM(F33:F35) | G36: =SUM(G33:G35) | H36: =SUM(H33:H35) | I36: =SUM(I33:I35) | J36: =SUM(J33:J35) | K36: =SUM(K33:K35)
B38: TEASER
B39: Campaña | C39: Inversión | D39: Inicio | E39: Fin | F39: Días | G39: Por día
B40: ='MP Cyber 2026'!B30 | C40: ='MP Cyber 2026'!F30 | D40: =Supuestos!$C$8 | E40: =Supuestos!$D$8 | F40: =Supuestos!$E$8 | G40: =IFERROR(C40/F40,"")
B41: ='MP Cyber 2026'!B31 | C41: ='MP Cyber 2026'!F31 | D41: =Supuestos!$C$8 | E41: =Supuestos!$D$8 | F41: =Supuestos!$E$8 | G41: =IFERROR(C41/F41,"")

Sheet Supuestos
B2: zenda.
B3: Sancor Seguros | Media Plan Cyber Monday 2026 · Supuestos
B4: Celdas en rosa: datos de ejemplo, pendientes de confirmar con el cliente. Texto azul: dato cargado a mano. Negro: fórmula.
B6: FECHAS
B7: Etapa | C7: Inicio | D7: Fin | E7: Días
B8: Teaser | C8: 46323 | D8: 46327 | E8: =D8-C8+1
B9: Cyber Monday + Cyber Week | C9: 46328 | D9: 46334 | E9: =D9-C9+1
B11: PRESUPUESTO POR PRODUCTO
B12: Producto | C12: Etapa | D12: Inversión | E12: % del total
B13: Teaser | C13: Teaser | D13: 325000 | E13: =IFERROR(D13/$D$18,"")
B14: Auto | C14: Performance | D14: 5700000 | E14: =IFERROR(D14/$D$18,"")
B15: Moto | C15: Performance | D15: 1500000 | E15: =IFERROR(D15/$D$18,"")
B16: Movilidad | C16: Performance | D16: 980000 | E16: =IFERROR(D16/$D$18,"")
B17: Hogar | C17: Performance | D17: 910000 | E17: =IFERROR(D17/$D$18,"")
B18: TOTAL | D18: =SUM(D13:D17) | E18: =SUM(E13:E17)
B20: REFERENCIA CYBER 2025 Y AJUSTE DE CONVERSIONES
B21: Producto | C21: Conv. proyectadas 2025 | D21: Conv. reales 2025 | E21: Cumplimiento 2025 | F21: Ajuste 2026 | G21: Comentario
B22: Auto | C22: 215 | D22: 169.24 | E22: =IFERROR(D22/C22,"") | F22: =MIN(1,E22) | G22: Por defecto, el cumplimiento 2025 (tope 100 %). Se puede pisar a mano.
B23: Moto | C23: 243 | D23: 234.71 | E23: =IFERROR(D23/C23,"") | F23: =MIN(1,E23) | G23: Por defecto, el cumplimiento 2025 (tope 100 %). Se puede pisar a mano.
B24: Movilidad | C24: 84 | D24: 55.61 | E24: =IFERROR(D24/C24,"") | F24: =MIN(1,E24) | G24: Por defecto, el cumplimiento 2025 (tope 100 %). Se puede pisar a mano.
B25: Hogar | C25: 16 | D25: 10 | E25: =IFERROR(D25/C25,"") | F25: =MIN(1,E25) | G25: Por defecto, el cumplimiento 2025 (tope 100 %). Se puede pisar a mano.
B26: Fuente: hoja "Conversiones - Plataforma" del MP Cyber 2025. El ajuste multiplica la Conv. Rate del mes anterior.
B28: DISTRIBUCIÓN DIARIA DE LA SEMANA CYBER
C29: Día 1 | D29: Día 2 | E29: Día 3 | F29: Día 4 | G29: Día 5 | H29: Día 6 | I29: Día 7
B30: Fecha | C30: =Supuestos!$C$9+0 | D30: =Supuestos!$C$9+1 | E30: =Supuestos!$C$9+2 | F30: =Supuestos!$C$9+3 | G30: =Supuestos!$C$9+4 | H30: =Supuestos!$C$9+5 | I30: =Supuestos!$C$9+6
B31: % de la inversión | C31: 0.17 | D31: 0.17 | E31: 0.16 | F31: 0.15 | G31: 0.13 | H31: 0.11 | I31: 0.11
B32: Control (debe dar 100 %) | C32: =SUM(C31:I31)
B33: Curva tomada del BGT Diario 2025. Si la semana cambia de largo, ajustar los días y que el control dé 100 %.
