Workbook

Sheet MP Cyber B2B
B2: zenda.
B3: pickit | Media Plan Cyber Monday B2B · Argentina 2026
B5: FLIGHT | C5: INVERSIÓN CONSERVADOR | F5: INVERSIÓN ARRIESGADO | I5: IMPRESIONES | M5: ALCANCE LINKEDIN
B6: =TEXT(Supuestos!$C$10,"dd/mm")&" al "&TEXT(Supuestos!$D$10,"dd/mm") | C6: =H39 | F6: =H49 | I6: =J39 | M6: =M34
B7: =Supuestos!$E$10&" días · Cyber Monday del "&TEXT(Supuestos!$C$9,"dd/mm")&" al "&TEXT(Supuestos!$D$9,"dd/mm") | C7: =TEXT(Supuestos!$C$22,"0.0")&" veces un día común" | F7: =TEXT(Supuestos!$C$23,"0.0")&" veces un día común" | I7: Escenario conservador | M7: Escenario conservador
B10: COMPARATIVO DE ESCENARIOS | H10: INVERSIÓN POR MEDIO
B11: Indicador | C11: Conservador | D11: Arriesgado | E11: Diferencia | H11: Medio | I11: Conservador | J11: % | K11: Arriesgado | L11: %
B12: Inversión | C12: =H39 | D12: =H49 | E12: =IFERROR(D12/C12-1,"") | H12: LinkedIn Ads | I12: =IF($D$34=H12,$H$34,0)+IF($D$36=H12,$H$36,0)+IF($D$37=H12,$H$37,0)+IF($D$38=H12,$H$38,0) | J12: =IFERROR(I12/$I$15,"") | K12: =IF($D$44=H12,$H$44,0)+IF($D$46=H12,$H$46,0)+IF($D$47=H12,$H$47,0)+IF($D$48=H12,$H$48,0) | L12: =IFERROR(K12/$K$15,"")
B13: Impresiones | C13: =J39 | D13: =J49 | E13: =IFERROR(D13/C13-1,"") | H13: Meta Ads | I13: =IF($D$34=H13,$H$34,0)+IF($D$36=H13,$H$36,0)+IF($D$37=H13,$H$37,0)+IF($D$38=H13,$H$38,0) | J13: =IFERROR(I13/$I$15,"") | K13: =IF($D$44=H13,$H$44,0)+IF($D$46=H13,$H$46,0)+IF($D$47=H13,$H$47,0)+IF($D$48=H13,$H$48,0) | L13: =IFERROR(K13/$K$15,"")
B14: Clics | C14: =K39 | D14: =K49 | E14: =IFERROR(D14/C14-1,"") | H14: Google Ads | I14: =IF($D$34=H14,$H$34,0)+IF($D$36=H14,$H$36,0)+IF($D$37=H14,$H$37,0)+IF($D$38=H14,$H$38,0) | J14: =IFERROR(I14/$I$15,"") | K14: =IF($D$44=H14,$H$44,0)+IF($D$46=H14,$H$46,0)+IF($D$47=H14,$H$47,0)+IF($D$48=H14,$H$48,0) | L14: =IFERROR(K14/$K$15,"")
B15: CTR | C15: =L39 | D15: =L49 | E15: =IFERROR(D15/C15-1,"") | H15: TOTAL | I15: =SUM(I12:I14) | J15: =SUM(J12:J14) | K15: =SUM(K12:K14) | L15: =SUM(L12:L14)
B16: Alcance LinkedIn | C16: =M34 | D16: =M44 | E16: =IFERROR(D16/C16-1,"") | H16: Meta: una sola campaña con presupuesto asignado por grupo de anuncios (público similar y remarketing).
B17: Frecuencia LinkedIn | C17: =N34 | D17: =N44 | E17: =IFERROR(D17/C17-1,"")
B18: Conversiones estimadas | C18: =O39 | D18: =O49 | E18: =IFERROR(D18/C18-1,"")
B19: Las conversiones son un indicador secundario: el objetivo de la campaña es presencia como aliado logístico.
B21: INVERSIÓN DIARIA VS. UN DÍA COMÚN DE B2B ARGENTINA
B22: Escenario | C22: Día común B2B AR | D22: Promedio diario | E22: Diferencia por día | F22: Veces un día común | H22: Día del Cyber Monday | I22: Veces un día común
B23: Conservador | C23: =Supuestos!$E$17 | D23: =I39 | E23: =D23-C23 | F23: =IFERROR(D23/C23,"") | H23: =H39*MAX(Supuestos!$C$40:$L$40) | I23: =IFERROR(H23/C23,"")
B24: Arriesgado | C24: =Supuestos!$E$17 | D24: =I49 | E24: =D24-C24 | F24: =IFERROR(D24/C24,"") | H24: =H49*MAX(Supuestos!$C$40:$L$40) | I24: =IFERROR(H24/C24,"")
B25: ="En el escenario conservador se invierten "&TEXT(E23,"$ #,##0")&" más por día que en un día común ("&TEXT(F23,"0.0")&" veces) y en los días del Cyber Monday "&TEXT(I23,"0.0")&" veces. En el arriesgado, "&TEXT(F24,"0.0")&" y "&TEXT(I24,"0.0")&" veces."
B26: Día común: inversión diaria real de las campañas B2B de Argentina en Google Ads, Meta Ads y LinkedIn Ads, 15/09 al 14/10/2026. En la semana del Cyber Monday todos los anunciantes suben su inversión; el plan acompaña esa suba para no perder visibilidad.
B29: PROYECCIÓN POR CAMPAÑA
B31: Escenario conservador
B32: CAMPAÑA | G32: INVERSIÓN | J32: RESULTADOS ESTIMADOS
B33: Campaña | C33: Grupo de anuncios | D33: Medio | E33: Objetivo | F33: Audiencia | G33: % | H33: Inversión | I33: Inv. diaria | J33: Impresiones | K33: Clics | L33: CTR | M33: Alcance | N33: Frecuencia | O33: Conversiones | P33: CPA
B34: AR_B2B_LinkedIn_Boost_Awareness_Cyber2026 | C34: Boost de posts | D34: LinkedIn Ads | E34: Reconocimiento | F34: Audiencia guardada B2B | G34: 0.3 | H34: =G34*Supuestos!$E$22 | I34: =IFERROR(H34/Supuestos!$E$10,"") | J34: =IFERROR(H34/($H$56*(1+Supuestos!$D$34))*1000,"") | K34: =IFERROR(H34/($I$56*(1+Supuestos!$D$34)),"") | L34: =IFERROR(K34/J34,"") | M34: =MIN(Supuestos!$D$29,J34/Supuestos!$D$30) | N34: =IFERROR(J34/M34,"") | O34: – | P34: –
B35: AR_B2B_FB_Trafico_Cyber2026 | C35: Total campaña (2 grupos) | D35: Meta Ads | E35: Tráfico web | G35: =SUM(G36:G37) | H35: =SUM(H36:H37) | I35: =SUM(I36:I37) | J35: =SUM(J36:J37) | K35: =SUM(K36:K37) | L35: =IFERROR(K35/J35,"") | M35: – | N35: – | O35: =SUM(O36:O37) | P35: =IFERROR(H35/O35,"")
C36: ↳ Público similar 1-3 % (BBDD) | D36: Meta Ads | E36: Tráfico web | F36: Similar a la base de datos | G36: 0.2 | H36: =G36*Supuestos!$E$22 | I36: =IFERROR(H36/Supuestos!$E$10,"") | J36: =IFERROR(H36/($H$57*(1+Supuestos!$D$34))*1000,"") | K36: =IFERROR(H36/($I$57*(1+Supuestos!$D$34)),"") | L36: =IFERROR(K36/J36,"") | M36: – | N36: – | O36: =IFERROR(K36*$K$57,"") | P36: =IFERROR(H36/O36,"")
C37: ↳ Remarketing BBDD | D37: Meta Ads | E37: Tráfico web | F37: Base de datos de clientes y leads | G37: 0.1 | H37: =G37*Supuestos!$E$22 | I37: =IFERROR(H37/Supuestos!$E$10,"") | J37: =IFERROR(H37/($H$57*(1+Supuestos!$D$34))*1000,"") | K37: =IFERROR(H37/($I$57*(1+Supuestos!$D$34)),"") | L37: =IFERROR(K37/J37,"") | M37: – | N37: – | O37: =IFERROR(K37*$K$57,"") | P37: =IFERROR(H37/O37,"")
B38: AR_B2B_GL_PMax_AliadoLogistico_Cyber2026 | C38: Grupo de recursos único | D38: Google Ads | E38: Conversiones | F38: Señales: términos de búsqueda + remarketing BBDD | G38: 0.4 | H38: =G38*Supuestos!$E$22 | I38: =IFERROR(H38/Supuestos!$E$10,"") | J38: =IFERROR(H38/($H$58*(1+Supuestos!$D$34))*1000,"") | K38: =IFERROR(H38/($I$58*(1+Supuestos!$D$34)),"") | L38: =IFERROR(K38/J38,"") | M38: – | N38: – | O38: =IFERROR(K38*$K$58,"") | P38: =IFERROR(H38/O38,"")
B39: Total escenario conservador | G39: =SUM(G34,G36,G37,G38) | H39: =SUM(H34,H36,H37,H38) | I39: =SUM(I34,I36,I37,I38) | J39: =SUM(J34,J36,J37,J38) | K39: =SUM(K34,K36,K37,K38) | L39: =IFERROR(K39/J39,"") | O39: =SUM(O34,O36,O37,O38) | P39: =IFERROR(SUM(H36,H37,H38)/O39,"")
B41: Escenario arriesgado
B42: CAMPAÑA | G42: INVERSIÓN | J42: RESULTADOS ESTIMADOS
B43: Campaña | C43: Grupo de anuncios | D43: Medio | E43: Objetivo | F43: Audiencia | G43: % | H43: Inversión | I43: Inv. diaria | J43: Impresiones | K43: Clics | L43: CTR | M43: Alcance | N43: Frecuencia | O43: Conversiones | P43: CPA
B44: AR_B2B_LinkedIn_Boost_Awareness_Cyber2026 | C44: Boost de posts | D44: LinkedIn Ads | E44: Reconocimiento | F44: Audiencia guardada B2B | G44: 0.2 | H44: =G44*Supuestos!$E$23 | I44: =IFERROR(H44/Supuestos!$E$10,"") | J44: =IFERROR(H44/($H$56*(1+Supuestos!$D$34))*1000,"") | K44: =IFERROR(H44/($I$56*(1+Supuestos!$D$34)),"") | L44: =IFERROR(K44/J44,"") | M44: =MIN(Supuestos!$D$29,J44/Supuestos!$D$30) | N44: =IFERROR(J44/M44,"") | O44: – | P44: –
B45: AR_B2B_FB_Trafico_Cyber2026 | C45: Total campaña (2 grupos) | D45: Meta Ads | E45: Tráfico web | G45: =SUM(G46:G47) | H45: =SUM(H46:H47) | I45: =SUM(I46:I47) | J45: =SUM(J46:J47) | K45: =SUM(K46:K47) | L45: =IFERROR(K45/J45,"") | M45: – | N45: – | O45: =SUM(O46:O47) | P45: =IFERROR(H45/O45,"")
C46: ↳ Público similar 1-3 % (BBDD) | D46: Meta Ads | E46: Tráfico web | F46: Similar a la base de datos | G46: 0.3 | H46: =G46*Supuestos!$E$23 | I46: =IFERROR(H46/Supuestos!$E$10,"") | J46: =IFERROR(H46/($H$57*(1+Supuestos!$D$34))*1000,"") | K46: =IFERROR(H46/($I$57*(1+Supuestos!$D$34)),"") | L46: =IFERROR(K46/J46,"") | M46: – | N46: – | O46: =IFERROR(K46*$K$57,"") | P46: =IFERROR(H46/O46,"")
C47: ↳ Remarketing BBDD | D47: Meta Ads | E47: Tráfico web | F47: Base de datos de clientes y leads | G47: 0.1 | H47: =G47*Supuestos!$E$23 | I47: =IFERROR(H47/Supuestos!$E$10,"") | J47: =IFERROR(H47/($H$57*(1+Supuestos!$D$34))*1000,"") | K47: =IFERROR(H47/($I$57*(1+Supuestos!$D$34)),"") | L47: =IFERROR(K47/J47,"") | M47: – | N47: – | O47: =IFERROR(K47*$K$57,"") | P47: =IFERROR(H47/O47,"")
B48: AR_B2B_GL_PMax_AliadoLogistico_Cyber2026 | C48: Grupo de recursos único | D48: Google Ads | E48: Conversiones | F48: Señales: términos de búsqueda + remarketing BBDD | G48: 0.4 | H48: =G48*Supuestos!$E$23 | I48: =IFERROR(H48/Supuestos!$E$10,"") | J48: =IFERROR(H48/($H$58*(1+Supuestos!$D$34))*1000,"") | K48: =IFERROR(H48/($I$58*(1+Supuestos!$D$34)),"") | L48: =IFERROR(K48/J48,"") | M48: – | N48: – | O48: =IFERROR(K48*$K$58,"") | P48: =IFERROR(H48/O48,"")
B49: Total escenario arriesgado | G49: =SUM(G44,G46,G47,G48) | H49: =SUM(H44,H46,H47,H48) | I49: =SUM(I44,I46,I47,I48) | J49: =SUM(J44,J46,J47,J48) | K49: =SUM(K44,K46,K47,K48) | L49: =IFERROR(K49/J49,"") | O49: =SUM(O44,O46,O47,O48) | P49: =IFERROR(SUM(H46,H47,H48)/O49,"")
...

Sheet BGT Diario
B2: zenda.
B3: Inversión diaria | Cyber B2B Argentina
B5: PLAN · ESCENARIO CONSERVADOR
B6: Campaña / grupo de anuncios | C6: Inversión | D6: =Supuestos!C39 | E6: =Supuestos!D39 | F6: =Supuestos!E39 | G6: =Supuestos!F39 | H6: =Supuestos!G39 | I6: =Supuestos!H39 | J6: =Supuestos!I39 | K6: =Supuestos!J39 | ... M6: =Supuestos!L39
B7: =IF('MP Cyber B2B'!B34="",'MP Cyber B2B'!B35&" · "&TRIM(SUBSTITUTE('MP Cyber B2B'!C34,"↳","")),'MP Cyber B2B'!B34) | C7: ='MP Cyber B2B'!H34 | D7: =$C7*Supuestos!C$40 | E7: =$C7*Supuestos!D$40 | F7: =$C7*Supuestos!E$40 | G7: =$C7*Supuestos!F$40 | H7: =$C7*Supuestos!G$40 | I7: =$C7*Supuestos!H$40 | J7: =$C7*Supuestos!I$40 | K7: =$C7*Supuestos!J$40 | ... M7: =$C7*Supuestos!L$40
B8: =IF('MP Cyber B2B'!B36="",'MP Cyber B2B'!B35&" · "&TRIM(SUBSTITUTE('MP Cyber B2B'!C36,"↳","")),'MP Cyber B2B'!B36) | C8: ='MP Cyber B2B'!H36 | D8: =$C8*Supuestos!C$40 | E8: =$C8*Supuestos!D$40 | F8: =$C8*Supuestos!E$40 | G8: =$C8*Supuestos!F$40 | H8: =$C8*Supuestos!G$40 | I8: =$C8*Supuestos!H$40 | J8: =$C8*Supuestos!I$40 | K8: =$C8*Supuestos!J$40 | ... M8: =$C8*Supuestos!L$40
B9: =IF('MP Cyber B2B'!B37="",'MP Cyber B2B'!B35&" · "&TRIM(SUBSTITUTE('MP Cyber B2B'!C37,"↳","")),'MP Cyber B2B'!B37) | C9: ='MP Cyber B2B'!H37 | D9: =$C9*Supuestos!C$40 | E9: =$C9*Supuestos!D$40 | F9: =$C9*Supuestos!E$40 | G9: =$C9*Supuestos!F$40 | H9: =$C9*Supuestos!G$40 | I9: =$C9*Supuestos!H$40 | J9: =$C9*Supuestos!I$40 | K9: =$C9*Supuestos!J$40 | ... M9: =$C9*Supuestos!L$40
B10: =IF('MP Cyber B2B'!B38="",'MP Cyber B2B'!B35&" · "&TRIM(SUBSTITUTE('MP Cyber B2B'!C38,"↳","")),'MP Cyber B2B'!B38) | C10: ='MP Cyber B2B'!H38 | D10: =$C10*Supuestos!C$40 | E10: =$C10*Supuestos!D$40 | F10: =$C10*Supuestos!E$40 | G10: =$C10*Supuestos!F$40 | H10: =$C10*Supuestos!G$40 | I10: =$C10*Supuestos!H$40 | J10: =$C10*Supuestos!I$40 | K10: =$C10*Supuestos!J$40 | ... M10: =$C10*Supuestos!L$40
B11: Total conservador | C11: =SUM(C7:C10) | D11: =SUM(D7:D10) | E11: =SUM(E7:E10) | F11: =SUM(F7:F10) | G11: =SUM(G7:G10) | H11: =SUM(H7:H10) | I11: =SUM(I7:I10) | J11: =SUM(J7:J10) | ... M11: =SUM(M7:M10)
B14: PLAN · ESCENARIO ARRIESGADO
B15: Campaña / grupo de anuncios | C15: Inversión | D15: =Supuestos!C39 | E15: =Supuestos!D39 | F15: =Supuestos!E39 | G15: =Supuestos!F39 | H15: =Supuestos!G39 | I15: =Supuestos!H39 | J15: =Supuestos!I39 | K15: =Supuestos!J39 | ... M15: =Supuestos!L39
B16: =IF('MP Cyber B2B'!B44="",'MP Cyber B2B'!B45&" · "&TRIM(SUBSTITUTE('MP Cyber B2B'!C44,"↳","")),'MP Cyber B2B'!B44) | C16: ='MP Cyber B2B'!H44 | D16: =$C16*Supuestos!C$40 | E16: =$C16*Supuestos!D$40 | F16: =$C16*Supuestos!E$40 | G16: =$C16*Supuestos!F$40 | H16: =$C16*Supuestos!G$40 | I16: =$C16*Supuestos!H$40 | J16: =$C16*Supuestos!I$40 | K16: =$C16*Supuestos!J$40 | ... M16: =$C16*Supuestos!L$40
B17: =IF('MP Cyber B2B'!B46="",'MP Cyber B2B'!B45&" · "&TRIM(SUBSTITUTE('MP Cyber B2B'!C46,"↳","")),'MP Cyber B2B'!B46) | C17: ='MP Cyber B2B'!H46 | D17: =$C17*Supuestos!C$40 | E17: =$C17*Supuestos!D$40 | F17: =$C17*Supuestos!E$40 | G17: =$C17*Supuestos!F$40 | H17: =$C17*Supuestos!G$40 | I17: =$C17*Supuestos!H$40 | J17: =$C17*Supuestos!I$40 | K17: =$C17*Supuestos!J$40 | ... M17: =$C17*Supuestos!L$40
B18: =IF('MP Cyber B2B'!B47="",'MP Cyber B2B'!B45&" · "&TRIM(SUBSTITUTE('MP Cyber B2B'!C47,"↳","")),'MP Cyber B2B'!B47) | C18: ='MP Cyber B2B'!H47 | D18: =$C18*Supuestos!C$40 | E18: =$C18*Supuestos!D$40 | F18: =$C18*Supuestos!E$40 | G18: =$C18*Supuestos!F$40 | H18: =$C18*Supuestos!G$40 | I18: =$C18*Supuestos!H$40 | J18: =$C18*Supuestos!I$40 | K18: =$C18*Supuestos!J$40 | ... M18: =$C18*Supuestos!L$40
B19: =IF('MP Cyber B2B'!B48="",'MP Cyber B2B'!B45&" · "&TRIM(SUBSTITUTE('MP Cyber B2B'!C48,"↳","")),'MP Cyber B2B'!B48) | C19: ='MP Cyber B2B'!H48 | D19: =$C19*Supuestos!C$40 | E19: =$C19*Supuestos!D$40 | F19: =$C19*Supuestos!E$40 | G19: =$C19*Supuestos!F$40 | H19: =$C19*Supuestos!G$40 | I19: =$C19*Supuestos!H$40 | J19: =$C19*Supuestos!I$40 | K19: =$C19*Supuestos!J$40 | ... M19: =$C19*Supuestos!L$40
B20: Total arriesgado | C20: =SUM(C16:C19) | D20: =SUM(D16:D19) | E20: =SUM(E16:E19) | F20: =SUM(F16:F19) | G20: =SUM(G16:G19) | H20: =SUM(H16:H19) | I20: =SUM(I16:I19) | J20: =SUM(J16:J19) | ... M20: =SUM(M16:M19)
B23: CONTROL DE CONSUMO
B24: ="Escenario controlado: "&Supuestos!$D$45
B25: Campaña / grupo de anuncios | C25: Inversión | D25: =Supuestos!C39 | E25: % | F25: =Supuestos!D39 | G25: % | H25: =Supuestos!E39 | I25: % | J25: =Supuestos!F39 | K25: % | L25: =Supuestos!G39 | M25: % | N25: =Supuestos!H39 | O25: % | P25: =Supuestos!I39 | Q25: % | R25: =Supuestos!J39 | S25: % | T25: =Supuestos!K39 | U25: % | V25: =Supuestos!L39 | W25: % | X25: Consumido | Y25: % del total
B26: =B7 | C26: =IF(Supuestos!$D$45="Arriesgado",C16,C7) | E26: =IF(D26="","",IFERROR(D26/IF(Supuestos!$D$45="Arriesgado",D16,D7),"")) | G26: =IF(F26="","",IFERROR(F26/IF(Supuestos!$D$45="Arriesgado",E16,E7),"")) | I26: =IF(H26="","",IFERROR(H26/IF(Supuestos!$D$45="Arriesgado",F16,F7),"")) | K26: =IF(J26="","",IFERROR(J26/IF(Supuestos!$D$45="Arriesgado",G16,G7),"")) | M26: =IF(L26="","",IFERROR(L26/IF(Supuestos!$D$45="Arriesgado",H16,H7),"")) | O26: =IF(N26="","",IFERROR(N26/IF(Supuestos!$D$45="Arriesgado",I16,I7),"")) | Q26: =IF(P26="","",IFERROR(P26/IF(Supuestos!$D$45="Arriesgado",J16,J7),"")) | S26: =IF(R26="","",IFERROR(R26/IF(Supuestos!$D$45="Arriesgado",K16,K7),"")) | U26: =IF(T26="","",IFERROR(T26/IF(Supuestos!$D$45="Arriesgado",L16,L7),"")) | W26: =IF(V26="","",IFERROR(V26/IF(Supuestos!$D$45="Arriesgado",M16,M7),"")) | X26: =SUM(D26,F26,H26,J26,L26,N26,P26,R26,T26,V26) | Y26: =IF(X26=0,"",IFERROR(X26/C26,""))
B27: =B8 | C27: =IF(Supuestos!$D$45="Arriesgado",C17,C8) | E27: =IF(D27="","",IFERROR(D27/IF(Supuestos!$D$45="Arriesgado",D17,D8),"")) | G27: =IF(F27="","",IFERROR(F27/IF(Supuestos!$D$45="Arriesgado",E17,E8),"")) | I27: =IF(H27="","",IFERROR(H27/IF(Supuestos!$D$45="Arriesgado",F17,F8),"")) | K27: =IF(J27="","",IFERROR(J27/IF(Supuestos!$D$45="Arriesgado",G17,G8),"")) | M27: =IF(L27="","",IFERROR(L27/IF(Supuestos!$D$45="Arriesgado",H17,H8),"")) | O27: =IF(N27="","",IFERROR(N27/IF(Supuestos!$D$45="Arriesgado",I17,I8),"")) | Q27: =IF(P27="","",IFERROR(P27/IF(Supuestos!$D$45="Arriesgado",J17,J8),"")) | S27: =IF(R27="","",IFERROR(R27/IF(Supuestos!$D$45="Arriesgado",K17,K8),"")) | U27: =IF(T27="","",IFERROR(T27/IF(Supuestos!$D$45="Arriesgado",L17,L8),"")) | W27: =IF(V27="","",IFERROR(V27/IF(Supuestos!$D$45="Arriesgado",M17,M8),"")) | X27: =SUM(D27,F27,H27,J27,L27,N27,P27,R27,T27,V27) | Y27: =IF(X27=0,"",IFERROR(X27/C27,""))
B28: =B9 | C28: =IF(Supuestos!$D$45="Arriesgado",C18,C9) | E28: =IF(D28="","",IFERROR(D28/IF(Supuestos!$D$45="Arriesgado",D18,D9),"")) | G28: =IF(F28="","",IFERROR(F28/IF(Supuestos!$D$45="Arriesgado",E18,E9),"")) | I28: =IF(H28="","",IFERROR(H28/IF(Supuestos!$D$45="Arriesgado",F18,F9),"")) | K28: =IF(J28="","",IFERROR(J28/IF(Supuestos!$D$45="Arriesgado",G18,G9),"")) | M28: =IF(L28="","",IFERROR(L28/IF(Supuestos!$D$45="Arriesgado",H18,H9),"")) | O28: =IF(N28="","",IFERROR(N28/IF(Supuestos!$D$45="Arriesgado",I18,I9),"")) | Q28: =IF(P28="","",IFERROR(P28/IF(Supuestos!$D$45="Arriesgado",J18,J9),"")) | S28: =IF(R28="","",IFERROR(R28/IF(Supuestos!$D$45="Arriesgado",K18,K9),"")) | U28: =IF(T28="","",IFERROR(T28/IF(Supuestos!$D$45="Arriesgado",L18,L9),"")) | W28: =IF(V28="","",IFERROR(V28/IF(Supuestos!$D$45="Arriesgado",M18,M9),"")) | X28: =SUM(D28,F28,H28,J28,L28,N28,P28,R28,T28,V28) | Y28: =IF(X28=0,"",IFERROR(X28/C28,""))
B29: =B10 | C29: =IF(Supuestos!$D$45="Arriesgado",C19,C10) | E29: =IF(D29="","",IFERROR(D29/IF(Supuestos!$D$45="Arriesgado",D19,D10),"")) | G29: =IF(F29="","",IFERROR(F29/IF(Supuestos!$D$45="Arriesgado",E19,E10),"")) | I29: =IF(H29="","",IFERROR(H29/IF(Supuestos!$D$45="Arriesgado",F19,F10),"")) | K29: =IF(J29="","",IFERROR(J29/IF(Supuestos!$D$45="Arriesgado",G19,G10),"")) | M29: =IF(L29="","",IFERROR(L29/IF(Supuestos!$D$45="Arriesgado",H19,H10),"")) | O29: =IF(N29="","",IFERROR(N29/IF(Supuestos!$D$45="Arriesgado",I19,I10),"")) | Q29: =IF(P29="","",IFERROR(P29/IF(Supuestos!$D$45="Arriesgado",J19,J10),"")) | S29: =IF(R29="","",IFERROR(R29/IF(Supuestos!$D$45="Arriesgado",K19,K10),"")) | U29: =IF(T29="","",IFERROR(T29/IF(Supuestos!$D$45="Arriesgado",L19,L10),"")) | W29: =IF(V29="","",IFERROR(V29/IF(Supuestos!$D$45="Arriesgado",M19,M10),"")) | X29: =SUM(D29,F29,H29,J29,L29,N29,P29,R29,T29,V29) | Y29: =IF(X29=0,"",IFERROR(X29/C29,""))
B30: Total | C30: =SUM(C26:C29) | D30: =IF(COUNT(D26:D29)=0,"",SUM(D26:D29)) | E30: =IF(D30="","",IFERROR(D30/IF(Supuestos!$D$45="Arriesgado",D20,D11),"")) | F30: =IF(COUNT(F26:F29)=0,"",SUM(F26:F29)) | G30: =IF(F30="","",IFERROR(F30/IF(Supuestos!$D$45="Arriesgado",E20,E11),"")) | H30: =IF(COUNT(H26:H29)=0,"",SUM(H26:H29)) | I30: =IF(H30="","",IFERROR(H30/IF(Supuestos!$D$45="Arriesgado",F20,F11),"")) | J30: =IF(COUNT(J26:J29)=0,"",SUM(J26:J29)) | K30: =IF(J30="","",IFERROR(J30/IF(Supuestos!$D$45="Arriesgado",G20,G11),"")) | L30: =IF(COUNT(L26:L29)=0,"",SUM(L26:L29)) | M30: =IF(L30="","",IFERROR(L30/IF(Supuestos!$D$45="Arriesgado",H20,H11),"")) | N30: =IF(COUNT(N26:N29)=0,"",SUM(N26:N29)) | O30: =IF(N30="","",IFERROR(N30/IF(Supuestos!$D$45="Arriesgado",I20,I11),"")) | P30: =IF(COUNT(P26:P29)=0,"",SUM(P26:P29)) | Q30: =IF(P30="","",IFERROR(P30/IF(Supuestos!$D$45="Arriesgado",J20,J11),"")) | R30: =IF(COUNT(R26:R29)=0,"",SUM(R26:R29)) | S30: =IF(R30="","",IFERROR(R30/IF(Supuestos!$D$45="Arriesgado",K20,K11),"")) | T30: =IF(COUNT(T26:T29)=0,"",SUM(T26:T29)) | U30: =IF(T30="","",IFERROR(T30/IF(Supuestos!$D$45="Arriesgado",L20,L11),"")) | V30: =IF(COUNT(V26:V29)=0,"",SUM(V26:V29)) | W30: =IF(V30="","",IFERROR(V30/IF(Supuestos!$D$45="Arriesgado",M20,M11),"")) | X30: =SUM(X26:X29) | Y30: =IF(X30=0,"",IFERROR(X30/C30,""))
B31: Cargar el consumo real de cada día. El % compara contra el plan del día: en verde entre 90 % y 110 %, en rosa fuera de ese rango.

Sheet Audiencias
B2: zenda.
B3: Audiencias y señales
B5: LINKEDIN ADS · BOOST DE POSTS
B6: Dato | C6: Detalle | D6: Estado
B7: Audiencia guardada
B8: Tamaño estimado
B9: Ubicación
B10: Cargos / seniority
B11: Industrias
B12: Tamaño de empresa
B14: META ADS · TRÁFICO WEB
B15: Dato | C15: Detalle | D15: Estado
B16: Grupo 1: público similar
B17: Base de origen
B18: Porcentaje de similitud
B19: Grupo 2: remarketing
B20: Base de datos
B21: Tamaño de la base
B23: GOOGLE ADS · PERFORMANCE MAX
B24: Dato | C24: Detalle | D24: Estado
B25: Señal: términos de búsqueda
B26: Señal: remarketing
B27: Mensaje central | C27: ¿Tu logística aguanta el pico de ventas?
B28: URL final

Sheet Supuestos
B2: zenda.
B3: Supuestos del Media Plan
B6: FECHAS
B7: Etapa | C7: Inicio | D7: Fin | E7: Días
B8: Previa al evento | C8: 46321 | D8: 46327 | E8: =D8-C8+1
B9: Cyber Monday | C9: 46328 | D9: 46330 | E9: =D9-C9+1
B10: Flight total | C10: =C8 | D10: =D9 | E10: =E8+E9
B12: DÍA COMÚN B2B ARGENTINA
B13: Medio | C13: Inversión del período | D13: Días | E13: Inversión diaria
B14: LinkedIn Ads | C14: 394682.1 | D14: 30 | E14: =IFERROR(C14/D14,"")
B15: Meta Ads | C15: 259305.43 | D15: 30 | E15: =IFERROR(C15/D15,"")
B16: Google Ads | C16: 2984777.3 | D16: 30 | E16: =IFERROR(C16/D16,"")
B17: Día común B2B Argentina | C17: =SUM(C14:C16) | E17: =SUM(E14:E16)
B18: Fuente: inversión real de las campañas B2B de Argentina en Google Ads, Meta Ads y LinkedIn Ads, 15/09 al 14/10/2026. LinkedIn incluye el boost de contenido AR & MX.
B20: PRESUPUESTO POR ESCENARIO
B21: Escenario | C21: Inversión diaria vs. día común | D21: Inversión diaria | E21: Inversión total
B22: Conservador | C22: 1.5 | D22: =Supuestos!$E$17*C22 | E22: =ROUND(D22*Supuestos!$E$10,-3)
B23: Arriesgado | C23: 3 | D23: =Supuestos!$E$17*C23 | E23: =ROUND(D23*Supuestos!$E$10,-3)
B24: El presupuesto total sale de multiplicar la inversión de un día común por el factor del escenario y por los días del flight.
B26: AUDIENCIA DE LINKEDIN
B27: Tamaño de la audiencia (miembros) | D27: 120000
B28: Cobertura máxima en el flight | D28: 0.5
B29: Alcance máximo | D29: =D27*D28
B30: Frecuencia mínima por persona | D30: 2.5
B31: Alcance = impresiones / frecuencia mínima, hasta el alcance máximo de la audiencia.
B33: AJUSTE DE COSTOS POR TEMPORADA
B34: Suba de CPM y CPC durante el flight | D34: 0.15
B35: Las subastas se encarecen en la semana del Cyber Monday porque todos los anunciantes aumentan su inversión.
B37: DISTRIBUCIÓN DIARIA DE LA INVERSIÓN
C38: Día 1 | D38: Día 2 | E38: Día 3 | F38: Día 4 | G38: Día 5 | H38: Día 6 | I38: Día 7 | J38: Día 8 | K38: Día 9 | L38: Día 10
B39: Fecha | C39: =Supuestos!$C$8+0 | D39: =Supuestos!$C$8+1 | E39: =Supuestos!$C$8+2 | F39: =Supuestos!$C$8+3 | G39: =Supuestos!$C$8+4 | H39: =Supuestos!$C$8+5 | I39: =Supuestos!$C$8+6 | J39: =Supuestos!$C$8+7 | K39: =Supuestos!$C$8+8 | L39: =Supuestos!$C$8+9
B40: % de la inversión | C40: 0.07 | D40: 0.07 | E40: 0.08 | F40: 0.08 | G40: 0.08 | H40: 0.08 | I40: 0.09 | J40: 0.15 | K40: 0.15 | L40: 0.15
B41: Total | C41: =SUM(C40:L40)
B42: La inversión crece en la previa y los tres días del Cyber Monday concentran el 45 %.
B44: ESCENARIO A CONTROLAR EN EL BGT
B45: Escenario aprobado | D45: Conservador
B47: CONTROLES
B48: Total conservador = presupuesto | D48: =IF(ROUND('MP Cyber B2B'!H39-Supuestos!$E$22,0)=0,"OK","REVISAR")
B49: Total arriesgado = presupuesto | D49: =IF(ROUND('MP Cyber B2B'!H49-Supuestos!$E$23,0)=0,"OK","REVISAR")
B50: % de cada escenario = 100 % | D50: =IF(AND(ROUND('MP Cyber B2B'!G39,4)=1,ROUND('MP Cyber B2B'!G49,4)=1),"OK","REVISAR")
...
